27.0.0.1 - - [26/Jul/2019 01:11:11] "POST /checktrue HTTP/1.1" 500 -
Traceback (most recent call last):
  File "C:\Program Files\Python37\lib\site-packages\flask\app.py", line 2463, in __call__
    return self.wsgi_app(environ, start_response)
  File "C:\Program Files\Python37\lib\site-packages\flask\app.py", line 2449, in wsgi_app
    response = self.handle_exception(e)
  File "C:\Program Files\Python37\lib\site-packages\flask\app.py", line 1866, in handle_exception
    reraise(exc_type, exc_value, tb)
  File "C:\Program Files\Python37\lib\site-packages\flask\_compat.py", line 39, in reraise
    raise value
  File "C:\Program Files\Python37\lib\site-packages\flask\app.py", line 2446, in wsgi_app
    response = self.full_dispatch_request()
  File "C:\Program Files\Python37\lib\site-packages\flask\app.py", line 1951, in full_dispatch_request
    rv = self.handle_user_exception(e)
  File "C:\Program Files\Python37\lib\site-packages\flask\app.py", line 1820, in handle_user_exception
    reraise(exc_type, exc_value, tb)
  File "C:\Program Files\Python37\lib\site-packages\flask\_compat.py", line 39, in reraise
    raise value
  File "C:\Program Files\Python37\lib\site-packages\flask\app.py", line 1949, in full_dispatch_request
    rv = self.dispatch_request()
  File "C:\Program Files\Python37\lib\site-packages\flask\app.py", line 1935, in dispatch_request
    return self.view_functions[rule.endpoint](**req.view_args)
  File "D:\git\GitHub-Desktop\e_drone_raspi\New Folder\run_flask.py", line 19, in checktrue
    return redirect(url_for('success', name = check))
  File "C:\Program Files\Python37\lib\site-packages\flask\helpers.py", line 370, in url_for
    return appctx.app.handle_url_build_error(error, endpoint, values)
  File "C:\Program Files\Python37\lib\site-packages\flask\app.py", line 2215, in handle_url_build_error
    reraise(exc_type, exc_value, tb)
  File "C:\Program Files\Python37\lib\site-packages\flask\_compat.py", line 39, in reraise
    raise value
  File "C:\Program Files\Python37\lib\site-packages\flask\helpers.py", line 358, in url_for
    endpoint, values, method=method, force_external=external
  File "C:\Program Files\Python37\lib\site-packages\werkzeug\routing.py", line 2020, in build
    raise BuildError(endpoint, values, method, self)
werkzeug.routing.BuildError: Could not build url for endpoint 'success' with values ['name']. Did you mean 'static' instead?
